Not Found: /favicon.ico
Internal Server Error: /Reporpoise/associate
Traceback (most recent call last):
  File "/Library/Python/2.7/site-packages/django/core/handlers/base.py", line 132, in get_response
    response = wrapped_callback(request, *callback_args, **callback_kwargs)
  File "/Users/Dave/Desktop/Github/Reporpoise/drug_search/views.py", line 12, in gene_table
    return render(request, 'drug_search/gene_association.html')
  File "/Library/Python/2.7/site-packages/django/shortcuts/__init__.py", line 53, in render
    return HttpResponse(loader.render_to_string(*args, **kwargs),
  File "/Library/Python/2.7/site-packages/django/template/loader.py", line 116, in render_to_string
    template_name, context, context_instance, dirs, dictionary)
  File "/Library/Python/2.7/site-packages/django/template/engine.py", line 217, in render_to_string
    return t.render(context_instance)
  File "/Library/Python/2.7/site-packages/django/template/base.py", line 209, in render
    return self._render(context)
  File "/Library/Python/2.7/site-packages/django/template/base.py", line 201, in _render
    return self.nodelist.render(context)
  File "/Library/Python/2.7/site-packages/django/template/base.py", line 903, in render
    bit = self.render_node(node, context)
  File "/Library/Python/2.7/site-packages/django/template/debug.py", line 79, in render_node
    return node.render(context)
  File "/Library/Python/2.7/site-packages/django/template/loader_tags.py", line 135, in render
    return compiled_parent._render(context)
  File "/Library/Python/2.7/site-packages/django/template/base.py", line 201, in _render
    return self.nodelist.render(context)
  File "/Library/Python/2.7/site-packages/django/template/base.py", line 903, in render
    bit = self.render_node(node, context)
  File "/Library/Python/2.7/site-packages/django/template/debug.py", line 79, in render_node
    return node.render(context)
  File "/Library/Python/2.7/site-packages/django/template/loader_tags.py", line 65, in render
    result = block.nodelist.render(context)
  File "/Library/Python/2.7/site-packages/django/template/base.py", line 903, in render
    bit = self.render_node(node, context)
  File "/Library/Python/2.7/site-packages/django/template/debug.py", line 79, in render_node
    return node.render(context)
  File "/Library/Python/2.7/site-packages/django/template/defaulttags.py", line 507, in render
    six.reraise(*exc_info)
  File "/Library/Python/2.7/site-packages/django/template/defaulttags.py", line 493, in render
    url = reverse(view_name, args=args, kwargs=kwargs, current_app=current_app)
  File "/Library/Python/2.7/site-packages/django/core/urlresolvers.py", line 579, in reverse
    return force_text(iri_to_uri(resolver._reverse_with_prefix(view, prefix, *args, **kwargs)))
  File "/Library/Python/2.7/site-packages/django/core/urlresolvers.py", line 496, in _reverse_with_prefix
    (lookup_view_s, args, kwargs, len(patterns), patterns))
NoReverseMatch: Reverse for 'drug_search/js/gene_association.js' with arguments '()' and keyword arguments '{}' not found. 0 pattern(s) tried: []
Internal Server Error: /Reporpoise/associate
Traceback (most recent call last):
  File "/Library/Python/2.7/site-packages/django/core/handlers/base.py", line 132, in get_response
    response = wrapped_callback(request, *callback_args, **callback_kwargs)
  File "/Users/Dave/Desktop/Github/Reporpoise/drug_search/views.py", line 12, in gene_table
    return render(request, 'drug_search/gene_association.html')
  File "/Library/Python/2.7/site-packages/django/shortcuts/__init__.py", line 53, in render
    return HttpResponse(loader.render_to_string(*args, **kwargs),
  File "/Library/Python/2.7/site-packages/django/template/loader.py", line 116, in render_to_string
    template_name, context, context_instance, dirs, dictionary)
  File "/Library/Python/2.7/site-packages/django/template/engine.py", line 217, in render_to_string
    return t.render(context_instance)
  File "/Library/Python/2.7/site-packages/django/template/base.py", line 209, in render
    return self._render(context)
  File "/Library/Python/2.7/site-packages/django/template/base.py", line 201, in _render
    return self.nodelist.render(context)
  File "/Library/Python/2.7/site-packages/django/template/base.py", line 903, in render
    bit = self.render_node(node, context)
  File "/Library/Python/2.7/site-packages/django/template/debug.py", line 79, in render_node
    return node.render(context)
  File "/Library/Python/2.7/site-packages/django/template/loader_tags.py", line 135, in render
    return compiled_parent._render(context)
  File "/Library/Python/2.7/site-packages/django/template/base.py", line 201, in _render
    return self.nodelist.render(context)
  File "/Library/Python/2.7/site-packages/django/template/base.py", line 903, in render
    bit = self.render_node(node, context)
  File "/Library/Python/2.7/site-packages/django/template/debug.py", line 79, in render_node
    return node.render(context)
  File "/Library/Python/2.7/site-packages/django/template/loader_tags.py", line 65, in render
    result = block.nodelist.render(context)
  File "/Library/Python/2.7/site-packages/django/template/base.py", line 903, in render
    bit = self.render_node(node, context)
  File "/Library/Python/2.7/site-packages/django/template/debug.py", line 79, in render_node
    return node.render(context)
  File "/Library/Python/2.7/site-packages/django/template/defaulttags.py", line 507, in render
    six.reraise(*exc_info)
  File "/Library/Python/2.7/site-packages/django/template/defaulttags.py", line 493, in render
    url = reverse(view_name, args=args, kwargs=kwargs, current_app=current_app)
  File "/Library/Python/2.7/site-packages/django/core/urlresolvers.py", line 579, in reverse
    return force_text(iri_to_uri(resolver._reverse_with_prefix(view, prefix, *args, **kwargs)))
  File "/Library/Python/2.7/site-packages/django/core/urlresolvers.py", line 496, in _reverse_with_prefix
    (lookup_view_s, args, kwargs, len(patterns), patterns))
NoReverseMatch: Reverse for 'drug_search/js/gene_association.js' with arguments '()' and keyword arguments '{}' not found. 0 pattern(s) tried: []
Internal Server Error: /Reporpoise/networktize
Traceback (most recent call last):
  File "/Library/Python/2.7/site-packages/django/core/handlers/base.py", line 132, in get_response
    response = wrapped_callback(request, *callback_args, **callback_kwargs)
  File "/Users/Dave/Desktop/Github/Reporpoise/drug_search/views.py", line 126, in networktize
    gene_list = dict(ast.literal_eval(request.GET['genes'])).keys()
  File "/System/Library/Frameworks/Python.framework/Versions/2.7/lib/python2.7/ast.py", line 80, in literal_eval
    return _convert(node_or_string)
  File "/System/Library/Frameworks/Python.framework/Versions/2.7/lib/python2.7/ast.py", line 79, in _convert
    raise ValueError('malformed string')
ValueError: malformed string
Internal Server Error: /Reporpoise/networktize
Traceback (most recent call last):
  File "/Library/Python/2.7/site-packages/django/core/handlers/base.py", line 132, in get_response
    response = wrapped_callback(request, *callback_args, **callback_kwargs)
  File "/Users/Dave/Desktop/Github/Reporpoise/drug_search/views.py", line 126, in networktize
    gene_list = dict(ast.literal_eval(request.GET['genes'])).keys()
  File "/System/Library/Frameworks/Python.framework/Versions/2.7/lib/python2.7/ast.py", line 80, in literal_eval
    return _convert(node_or_string)
  File "/System/Library/Frameworks/Python.framework/Versions/2.7/lib/python2.7/ast.py", line 79, in _convert
    raise ValueError('malformed string')
ValueError: malformed string
Not Found: /drug_search
Not Found: /favicon.ico
Not Found: /favicon.ico
Not Found: /favicon.ico
Internal Server Error: /Reporpoise/search
Traceback (most recent call last):
  File "/Library/Python/2.7/site-packages/django/core/handlers/base.py", line 132, in get_response
    response = wrapped_callback(request, *callback_args, **callback_kwargs)
  File "/Users/Dave/Desktop/Github/Reporpoise/drug_search/views.py", line 48, in search
    gene_name = Gene.objects.filter(gene_id__iexact=gene_name)[0].gene_name
  File "/Library/Python/2.7/site-packages/django/db/models/query.py", line 201, in __getitem__
    return list(qs)[0]
IndexError: list index out of range
Not Found: /
Internal Server Error: /Reporpoise/network
Traceback (most recent call last):
  File "/Library/Python/2.7/site-packages/django/core/handlers/base.py", line 132, in get_response
    response = wrapped_callback(request, *callback_args, **callback_kwargs)
  File "/Users/Dave/Desktop/Github/Reporpoise/drug_search/views.py", line 31, in network
    return render(request,'drug_search/network.html',{"gene_network":json.dumps({gene_name:""}),"phenotypes":phenotypes,"mode":mode,"connection":connection,"source":source})
UnboundLocalError: local variable 'gene_name' referenced before assignment
Internal Server Error: /Reporpoise/network
Traceback (most recent call last):
  File "/Library/Python/2.7/site-packages/django/core/handlers/base.py", line 132, in get_response
    response = wrapped_callback(request, *callback_args, **callback_kwargs)
  File "/Users/Dave/Desktop/Github/Reporpoise/drug_search/views.py", line 31, in network
    return render(request,'drug_search/network.html',{"gene_network":json.dumps({gene_name:""}),"phenotypes":phenotypes,"mode":mode,"connection":connection,"source":source})
UnboundLocalError: local variable 'gene_name' referenced before assignment
Not Found: /Reporpoise/test.html
Not Found: /favicon.ico
Not Found: /favicon.ico
Internal Server Error: /Reporpoise/networktize
Traceback (most recent call last):
  File "/Library/Python/2.7/site-packages/django/core/handlers/base.py", line 132, in get_response
    response = wrapped_callback(request, *callback_args, **callback_kwargs)
  File "/Users/Dave/Desktop/Github/Reporpoise/drug_search/views.py", line 146, in networktize
    print interactoin.gene_target.gene_name
NameError: global name 'interactoin' is not defined
Internal Server Error: /Reporpoise/networktize
Traceback (most recent call last):
  File "/Library/Python/2.7/site-packages/django/core/handlers/base.py", line 132, in get_response
    response = wrapped_callback(request, *callback_args, **callback_kwargs)
  File "/Users/Dave/Desktop/Github/Reporpoise/drug_search/views.py", line 191, in networktize
    network_graph["links"].append({"source":interaction_indicies[interaction.gene_source.gene_name],"target":interaction_indicies[interaction.gene_target.gene_name],"type":case})
NameError: global name 'case' is not defined
Not Found: /favicon.ico
Not Found: /favicon.ico
Not Found: /Reporpoise/search
Not Found: /favicon.ico
Not Found: /favicon.ico
Not Found: /favicon.ico
Not Found: /favicon.ico
Not Found: /test
Not Found: /favicon.ico
Not Found: /favicon.ico
Not Found: /
Not Found: /favicon.ico
Not Found: /favicon.ico
Not Found: /
Not Found: /favicon.ico
Not Found: /favicon.ico
Not Found: /
Not Found: /favicon.ico
Not Found: /favicon.ico
Not Found: /
Not Found: /favicon.ico
Not Found: /favicon.ico
Not Found: /
Not Found: /favicon.ico
Not Found: /favicon.ico
Not Found: /favicon.ico
Not Found: /favicon.ico
Internal Server Error: /Reporpoise/grab_data
Traceback (most recent call last):
  File "/Library/Python/2.7/site-packages/django/core/handlers/base.py", line 132, in get_response
    response = wrapped_callback(request, *callback_args, **callback_kwargs)
  File "/Users/Dave/Desktop/Github/Reporpoise/drug_search/views.py", line 74, in grab_data
    pheno_list.append(gene_pheno.phenotype.name)
AttributeError: 'set' object has no attribute 'append'
Internal Server Error: /Reporpoise/grab_data
Traceback (most recent call last):
  File "/Library/Python/2.7/site-packages/django/core/handlers/base.py", line 132, in get_response
    response = wrapped_callback(request, *callback_args, **callback_kwargs)
  File "/Users/Dave/Desktop/Github/Reporpoise/drug_search/views.py", line 74, in grab_data
    pheno_list.append(gene_pheno.phenotype.name)
AttributeError: 'Phenotype' object has no attribute 'phenotype'
Internal Server Error: /Reporpoise/grab_data
Traceback (most recent call last):
  File "/Library/Python/2.7/site-packages/django/core/handlers/base.py", line 132, in get_response
    response = wrapped_callback(request, *callback_args, **callback_kwargs)
  File "/Users/Dave/Desktop/Github/Reporpoise/drug_search/views.py", line 70, in grab_data
    gene_dict = {gene_id: Phenotypemap.objects.filter(gene__gene_name__iexact=gene_id) for gene_id in gene_list}
  File "/Users/Dave/Desktop/Github/Reporpoise/drug_search/views.py", line 70, in <dictcomp>
    gene_dict = {gene_id: Phenotypemap.objects.filter(gene__gene_name__iexact=gene_id) for gene_id in gene_list}
NameError: global name 'Phenotypemap' is not defined
Internal Server Error: /Reporpoise/grab_data
Traceback (most recent call last):
  File "/Library/Python/2.7/site-packages/django/core/handlers/base.py", line 132, in get_response
    response = wrapped_callback(request, *callback_args, **callback_kwargs)
  File "/Users/Dave/Desktop/Github/Reporpoise/drug_search/views.py", line 75, in grab_data
    temp_gene_dict[gene_id].append((gene_pheno.phenotype.name,gene_pheno.z_score))
AttributeError: 'PhenotypeMap' object has no attribute 'z_score'
Internal Server Error: /Reporpoise/grab_data
Traceback (most recent call last):
  File "/Library/Python/2.7/site-packages/django/core/handlers/base.py", line 132, in get_response
    response = wrapped_callback(request, *callback_args, **callback_kwargs)
  File "/Users/Dave/Desktop/Github/Reporpoise/drug_search/views.py", line 66, in grab_data
    gene_source = request.GET['gene_source']
  File "/Library/Python/2.7/site-packages/django/utils/datastructures.py", line 322, in __getitem__
    raise MultiValueDictKeyError(repr(key))
MultiValueDictKeyError: "'gene_source'"
Internal Server Error: /Reporpoise/grab_data
Traceback (most recent call last):
  File "/Library/Python/2.7/site-packages/django/core/handlers/base.py", line 132, in get_response
    response = wrapped_callback(request, *callback_args, **callback_kwargs)
  File "/Users/Dave/Desktop/Github/Reporpoise/drug_search/views.py", line 69, in grab_data
    gene_source = request.GET['gene_source']
  File "/Library/Python/2.7/site-packages/django/utils/datastructures.py", line 322, in __getitem__
    raise MultiValueDictKeyError(repr(key))
MultiValueDictKeyError: "'gene_source'"
Internal Server Error: /Reporpoise/network
Traceback (most recent call last):
  File "/Library/Python/2.7/site-packages/django/core/handlers/base.py", line 132, in get_response
    response = wrapped_callback(request, *callback_args, **callback_kwargs)
  File "/Users/Dave/Desktop/Github/Reporpoise/drug_search/views.py", line 32, in network
    return render(request,'drug_search/network.html',{"gene_network":json.dumps({gene_name:""}),"phenotypes":phenotypes,"mode":mode,"connection":connection,"source":source,"gene_source":gene_source})
UnboundLocalError: local variable 'gene_name' referenced before assignment
Internal Server Error: /Reporpoise/grab_data
Traceback (most recent call last):
  File "/Library/Python/2.7/site-packages/django/core/handlers/base.py", line 132, in get_response
    response = wrapped_callback(request, *callback_args, **callback_kwargs)
  File "/Users/Dave/Desktop/Github/Reporpoise/drug_search/views.py", line 69, in grab_data
    gene_source = request.GET['gene_source']
  File "/Library/Python/2.7/site-packages/django/utils/datastructures.py", line 322, in __getitem__
    raise MultiValueDictKeyError(repr(key))
MultiValueDictKeyError: "'gene_source'"
Internal Server Error: /Reporpoise/network
Traceback (most recent call last):
  File "/Library/Python/2.7/site-packages/django/core/handlers/base.py", line 132, in get_response
    response = wrapped_callback(request, *callback_args, **callback_kwargs)
  File "/Users/Dave/Desktop/Github/Reporpoise/drug_search/views.py", line 32, in network
    return render(request,'drug_search/network.html',{"gene_network":json.dumps({gene_name:""}),"phenotypes":phenotypes,"mode":mode,"connection":connection,"source":source,"gene_source":gene_source})
UnboundLocalError: local variable 'gene_name' referenced before assignment
Internal Server Error: /Reporpoise/grab_data
Traceback (most recent call last):
  File "/Library/Python/2.7/site-packages/django/core/handlers/base.py", line 132, in get_response
    response = wrapped_callback(request, *callback_args, **callback_kwargs)
  File "/Users/Dave/Desktop/Github/Reporpoise/drug_search/views.py", line 69, in grab_data
    gene_source = request.GET['gene_source']
  File "/Library/Python/2.7/site-packages/django/utils/datastructures.py", line 322, in __getitem__
    raise MultiValueDictKeyError(repr(key))
MultiValueDictKeyError: "'gene_source'"
Internal Server Error: /Reporpoise/network
Traceback (most recent call last):
  File "/Library/Python/2.7/site-packages/django/core/handlers/base.py", line 132, in get_response
    response = wrapped_callback(request, *callback_args, **callback_kwargs)
  File "/Users/Dave/Desktop/Github/Reporpoise/drug_search/views.py", line 32, in network
    return render(request,'drug_search/network.html',{"gene_network":json.dumps({gene_name:""}),"phenotypes":phenotypes,"mode":mode,"connection":connection,"source":source,"gene_source":gene_source})
UnboundLocalError: local variable 'gene_name' referenced before assignment
Internal Server Error: /Reporpoise/grab_data
Traceback (most recent call last):
  File "/Library/Python/2.7/site-packages/django/core/handlers/base.py", line 132, in get_response
    response = wrapped_callback(request, *callback_args, **callback_kwargs)
  File "/Users/Dave/Desktop/Github/Reporpoise/drug_search/views.py", line 72, in grab_data
    gene_dict = {gene_id: PhenotypeMap.objects.filter(Q(gene__gene_name__iexact=gene_id) & Q(source__name__iexact=gene_source)) for gene_id in gene_list}
  File "/Users/Dave/Desktop/Github/Reporpoise/drug_search/views.py", line 72, in <dictcomp>
    gene_dict = {gene_id: PhenotypeMap.objects.filter(Q(gene__gene_name__iexact=gene_id) & Q(source__name__iexact=gene_source)) for gene_id in gene_list}
  File "/Library/Python/2.7/site-packages/django/db/models/manager.py", line 127, in manager_method
    return getattr(self.get_queryset(), name)(*args, **kwargs)
  File "/Library/Python/2.7/site-packages/django/db/models/query.py", line 679, in filter
    return self._filter_or_exclude(False, *args, **kwargs)
  File "/Library/Python/2.7/site-packages/django/db/models/query.py", line 697, in _filter_or_exclude
    clone.query.add_q(Q(*args, **kwargs))
  File "/Library/Python/2.7/site-packages/django/db/models/sql/query.py", line 1304, in add_q
    clause, require_inner = self._add_q(where_part, self.used_aliases)
  File "/Library/Python/2.7/site-packages/django/db/models/sql/query.py", line 1326, in _add_q
    current_negated, allow_joins, split_subq)
  File "/Library/Python/2.7/site-packages/django/db/models/sql/query.py", line 1332, in _add_q
    allow_joins=allow_joins, split_subq=split_subq,
  File "/Library/Python/2.7/site-packages/django/db/models/sql/query.py", line 1194, in build_filter
    lookups, value)
  File "/Library/Python/2.7/site-packages/django/db/models/fields/related.py", line 1709, in get_lookup_constraint
    raise exceptions.FieldError('Relation fields do not support nested lookups')
FieldError: Relation fields do not support nested lookups
Internal Server Error: /Reporpoise/grab_data
Traceback (most recent call last):
  File "/Library/Python/2.7/site-packages/django/core/handlers/base.py", line 132, in get_response
    response = wrapped_callback(request, *callback_args, **callback_kwargs)
  File "/Users/Dave/Desktop/Github/Reporpoise/drug_search/views.py", line 78, in grab_data
    print gene_source in gene_pheno.source
TypeError: argument of type 'GeneScoreSource' is not iterable
Internal Server Error: /Reporpoise/grab_data
Traceback (most recent call last):
  File "/Library/Python/2.7/site-packages/django/core/handlers/base.py", line 132, in get_response
    response = wrapped_callback(request, *callback_args, **callback_kwargs)
  File "/Users/Dave/Desktop/Github/Reporpoise/drug_search/views.py", line 79, in grab_data
    if gene_source in gene_pheno.source:
TypeError: argument of type 'GeneScoreSource' is not iterable
Internal Server Error: /Reporpoise/grab_data
Traceback (most recent call last):
  File "/Library/Python/2.7/site-packages/django/core/handlers/base.py", line 132, in get_response
    response = wrapped_callback(request, *callback_args, **callback_kwargs)
  File "/Users/Dave/Desktop/Github/Reporpoise/drug_search/views.py", line 79, in grab_data
    print len(gene_pheno.source)
TypeError: object of type 'GeneScoreSource' has no len()
Not Found: /Reporpoise/update_graph('CHD')
Not Found: /favicon.ico
Not Found: /favicon.ico
Not Found: /test
Not Found: /favicon.ico
Not Found: /favicon.ico
Not Found: /favicon.ico
Internal Server Error: /Reporpoise/grab_data
Traceback (most recent call last):
  File "/Library/Python/2.7/site-packages/django/core/handlers/base.py", line 132, in get_response
    response = wrapped_callback(request, *callback_args, **callback_kwargs)
  File "/Users/Dave/Desktop/Github/Reporpoise/drug_search/views.py", line 102, in grab_data
    if tar.gene.gene_name in target:
  File "/Library/Python/2.7/site-packages/django/db/models/fields/related.py", line 602, in __get__
    rel_obj = qs.get()
  File "/Library/Python/2.7/site-packages/django/db/models/query.py", line 328, in get
    num = len(clone)
  File "/Library/Python/2.7/site-packages/django/db/models/query.py", line 144, in __len__
    self._fetch_all()
  File "/Library/Python/2.7/site-packages/django/db/models/query.py", line 965, in _fetch_all
    self._result_cache = list(self.iterator())
  File "/Library/Python/2.7/site-packages/django/db/models/query.py", line 238, in iterator
    results = compiler.execute_sql()
  File "/Library/Python/2.7/site-packages/django/db/models/sql/compiler.py", line 840, in execute_sql
    cursor.execute(sql, params)
  File "/Library/Python/2.7/site-packages/django/db/backends/utils.py", line 79, in execute
    return super(CursorDebugWrapper, self).execute(sql, params)
  File "/Library/Python/2.7/site-packages/django/db/backends/utils.py", line 64, in execute
    return self.cursor.execute(sql, params)
  File "/Library/Python/2.7/site-packages/django/db/utils.py", line 97, in __exit__
    six.reraise(dj_exc_type, dj_exc_value, traceback)
  File "/Library/Python/2.7/site-packages/django/db/backends/utils.py", line 64, in execute
    return self.cursor.execute(sql, params)
  File "/Library/Python/2.7/site-packages/django/db/backends/sqlite3/base.py", line 318, in execute
    return Database.Cursor.execute(self, query, params)
OperationalError: no such column: drug_search_gene.start
Internal Server Error: /Reporpoise/network
Traceback (most recent call last):
  File "/Library/Python/2.7/site-packages/django/core/handlers/base.py", line 132, in get_response
    response = wrapped_callback(request, *callback_args, **callback_kwargs)
  File "/Users/Dave/Desktop/Github/Reporpoise/drug_search/views.py", line 32, in network
    return render(request,'drug_search/network.html',{"gene_network":json.dumps({gene_name:""}),"phenotypes":phenotypes,"mode":mode,"connection":connection,"source":source,"gene_source":gene_source})
UnboundLocalError: local variable 'gene_name' referenced before assignment
Not Found: /Reporpoise/search
Not Found: /Reporpoise/search
Not Found: /favicon.ico
Not Found: /favicon.ico
Forbidden (CSRF cookie not set.): /Reporpoise/network
Internal Server Error: /Reporpoise/search
Traceback (most recent call last):
  File "/Library/Python/2.7/site-packages/django/core/handlers/base.py", line 108, in get_response
    response = middleware_method(request)
  File "/Library/Python/2.7/site-packages/django/middleware/common.py", line 74, in process_request
    if (not urlresolvers.is_valid_path(request.path_info, urlconf) and
  File "/Library/Python/2.7/site-packages/django/core/urlresolvers.py", line 647, in is_valid_path
    resolve(path, urlconf)
  File "/Library/Python/2.7/site-packages/django/core/urlresolvers.py", line 522, in resolve
    return get_resolver(urlconf).resolve(path)
  File "/Library/Python/2.7/site-packages/django/core/urlresolvers.py", line 366, in resolve
    for pattern in self.url_patterns:
  File "/Library/Python/2.7/site-packages/django/core/urlresolvers.py", line 402, in url_patterns
    patterns = getattr(self.urlconf_module, "urlpatterns", self.urlconf_module)
  File "/Library/Python/2.7/site-packages/django/core/urlresolvers.py", line 396, in urlconf_module
    self._urlconf_module = import_module(self.urlconf_name)
  File "/usr/local/Cellar/python/2.7.9/Frameworks/Python.framework/Versions/2.7/lib/python2.7/importlib/__init__.py", line 37, in import_module
    __import__(name)
  File "/Users/Dave/Desktop/Github/Reporpoise/reporpoise/urls.py", line 21, in <module>
    url(r'^Reporpoise/', include('drug_search.urls')),
  File "/Library/Python/2.7/site-packages/django/conf/urls/__init__.py", line 33, in include
    urlconf_module = import_module(urlconf_module)
  File "/usr/local/Cellar/python/2.7.9/Frameworks/Python.framework/Versions/2.7/lib/python2.7/importlib/__init__.py", line 37, in import_module
    __import__(name)
  File "/Users/Dave/Desktop/Github/Reporpoise/drug_search/urls.py", line 3, in <module>
    from . import views
  File "/Users/Dave/Desktop/Github/Reporpoise/drug_search/views.py", line 78
    print gene_source == gene_pheno.source.source:
                                                 ^
SyntaxError: invalid syntax
Internal Server Error: /Reporpoise/search
Traceback (most recent call last):
  File "/Library/Python/2.7/site-packages/django/core/handlers/base.py", line 108, in get_response
    response = middleware_method(request)
  File "/Library/Python/2.7/site-packages/django/middleware/common.py", line 74, in process_request
    if (not urlresolvers.is_valid_path(request.path_info, urlconf) and
  File "/Library/Python/2.7/site-packages/django/core/urlresolvers.py", line 647, in is_valid_path
    resolve(path, urlconf)
  File "/Library/Python/2.7/site-packages/django/core/urlresolvers.py", line 522, in resolve
    return get_resolver(urlconf).resolve(path)
  File "/Library/Python/2.7/site-packages/django/core/urlresolvers.py", line 366, in resolve
    for pattern in self.url_patterns:
  File "/Library/Python/2.7/site-packages/django/core/urlresolvers.py", line 402, in url_patterns
    patterns = getattr(self.urlconf_module, "urlpatterns", self.urlconf_module)
  File "/Library/Python/2.7/site-packages/django/core/urlresolvers.py", line 396, in urlconf_module
    self._urlconf_module = import_module(self.urlconf_name)
  File "/usr/local/Cellar/python/2.7.9/Frameworks/Python.framework/Versions/2.7/lib/python2.7/importlib/__init__.py", line 37, in import_module
    __import__(name)
  File "/Users/Dave/Desktop/Github/Reporpoise/reporpoise/urls.py", line 21, in <module>
    url(r'^Reporpoise/', include('drug_search.urls')),
  File "/Library/Python/2.7/site-packages/django/conf/urls/__init__.py", line 33, in include
    urlconf_module = import_module(urlconf_module)
  File "/usr/local/Cellar/python/2.7.9/Frameworks/Python.framework/Versions/2.7/lib/python2.7/importlib/__init__.py", line 37, in import_module
    __import__(name)
  File "/Users/Dave/Desktop/Github/Reporpoise/drug_search/urls.py", line 3, in <module>
    from . import views
  File "/Users/Dave/Desktop/Github/Reporpoise/drug_search/views.py", line 78
    print gene_source == gene_pheno.source.source:
                                                 ^
SyntaxError: invalid syntax
Not Found: /Reporpoise/search
Not Found: /favicon.ico
Not Found: /Reporpoise/show_slides
Internal Server Error: /Reporpoise/show_slides
Traceback (most recent call last):
  File "/Library/Python/2.7/site-packages/django/core/handlers/base.py", line 108, in get_response
    response = middleware_method(request)
  File "/Library/Python/2.7/site-packages/django/middleware/common.py", line 74, in process_request
    if (not urlresolvers.is_valid_path(request.path_info, urlconf) and
  File "/Library/Python/2.7/site-packages/django/core/urlresolvers.py", line 647, in is_valid_path
    resolve(path, urlconf)
  File "/Library/Python/2.7/site-packages/django/core/urlresolvers.py", line 522, in resolve
    return get_resolver(urlconf).resolve(path)
  File "/Library/Python/2.7/site-packages/django/core/urlresolvers.py", line 366, in resolve
    for pattern in self.url_patterns:
  File "/Library/Python/2.7/site-packages/django/core/urlresolvers.py", line 402, in url_patterns
    patterns = getattr(self.urlconf_module, "urlpatterns", self.urlconf_module)
  File "/Library/Python/2.7/site-packages/django/core/urlresolvers.py", line 396, in urlconf_module
    self._urlconf_module = import_module(self.urlconf_name)
  File "/usr/local/Cellar/python/2.7.9/Frameworks/Python.framework/Versions/2.7/lib/python2.7/importlib/__init__.py", line 37, in import_module
    __import__(name)
  File "/Users/Dave/Desktop/Github/Reporpoise/reporpoise/urls.py", line 21, in <module>
    url(r'^Reporpoise/', include('drug_search.urls')),
  File "/Library/Python/2.7/site-packages/django/conf/urls/__init__.py", line 33, in include
    urlconf_module = import_module(urlconf_module)
  File "/usr/local/Cellar/python/2.7.9/Frameworks/Python.framework/Versions/2.7/lib/python2.7/importlib/__init__.py", line 37, in import_module
    __import__(name)
  File "/Users/Dave/Desktop/Github/Reporpoise/drug_search/urls.py", line 14
    url(r'^show_slides$',views.show_slides,name="show_slides")
      ^
SyntaxError: invalid syntax
Internal Server Error: /Reporpoise/show_slides
Traceback (most recent call last):
  File "/Library/Python/2.7/site-packages/django/core/handlers/base.py", line 132, in get_response
    response = wrapped_callback(request, *callback_args, **callback_kwargs)
  File "/Users/Dave/Desktop/Github/Reporpoise/drug_search/views.py", line 9, in show_slides
    return render(request, 'drug_serach/slides.html')
NameError: global name 'request' is not defined
Internal Server Error: /Reporpoise/show_slides
Traceback (most recent call last):
  File "/Library/Python/2.7/site-packages/django/core/handlers/base.py", line 132, in get_response
    response = wrapped_callback(request, *callback_args, **callback_kwargs)
  File "/Users/Dave/Desktop/Github/Reporpoise/drug_search/views.py", line 9, in show_slides
    return render(request, 'drug_serach/slides.html')
  File "/Library/Python/2.7/site-packages/django/shortcuts/__init__.py", line 53, in render
    return HttpResponse(loader.render_to_string(*args, **kwargs),
  File "/Library/Python/2.7/site-packages/django/template/loader.py", line 138, in render_to_string
    raise TemplateDoesNotExist(template_name)
TemplateDoesNotExist: drug_serach/slides.html
Not Found: /Reporpoise/plugin/highlight/highlight.js
Not Found: /Reporpoise/plugin/zoom-js/zoom.js
Not Found: /Reporpoise/plugin/notes/notes.js
Not Found: /Reporpoise/plugin/highlight/highlight.js
Not Found: /Reporpoise/plugin/zoom-js/zoom.js
Not Found: /Reporpoise/plugin/notes/notes.js
Internal Server Error: /Reporpoise/show_slides
Traceback (most recent call last):
  File "/Library/Python/2.7/site-packages/django/core/handlers/base.py", line 132, in get_response
    response = wrapped_callback(request, *callback_args, **callback_kwargs)
  File "/Users/Dave/Desktop/Github/Reporpoise/drug_search/views.py", line 9, in show_slides
    return render(request, 'drug_search/slides.html')
  File "/Library/Python/2.7/site-packages/django/shortcuts/__init__.py", line 53, in render
    return HttpResponse(loader.render_to_string(*args, **kwargs),
  File "/Library/Python/2.7/site-packages/django/template/loader.py", line 116, in render_to_string
    template_name, context, context_instance, dirs, dictionary)
  File "/Library/Python/2.7/site-packages/django/template/engine.py", line 208, in render_to_string
    t = self.get_template(template_name, dirs)
  File "/Library/Python/2.7/site-packages/django/template/engine.py", line 167, in get_template
    template, origin = self.find_template(template_name, dirs)
  File "/Library/Python/2.7/site-packages/django/template/engine.py", line 141, in find_template
    source, display_name = loader(name, dirs)
  File "/Library/Python/2.7/site-packages/django/template/loaders/base.py", line 13, in __call__
    return self.load_template(template_name, template_dirs)
  File "/Library/Python/2.7/site-packages/django/template/loaders/base.py", line 23, in load_template
    template = Template(source, origin, template_name, self.engine)
  File "/Library/Python/2.7/site-packages/django/template/base.py", line 190, in __init__
    self.nodelist = engine.compile_string(template_string, origin)
  File "/Library/Python/2.7/site-packages/django/template/engine.py", line 261, in compile_string
    return parser.parse()
  File "/Library/Python/2.7/site-packages/django/template/base.py", line 341, in parse
    compiled_result = compile_func(self, token)
  File "/Library/Python/2.7/site-packages/django/contrib/staticfiles/templatetags/staticfiles.py", line 37, in do_static
    return StaticFilesNode.handle_token(parser, token)
  File "/Library/Python/2.7/site-packages/django/templatetags/static.py", line 126, in handle_token
    path = parser.compile_filter(bits[1])
  File "/Library/Python/2.7/site-packages/django/template/base.py", line 423, in compile_filter
    return FilterExpression(token, self)
  File "/Library/Python/2.7/site-packages/django/template/base.py", line 639, in __init__
    "from '%s'" % (token[upto:], token))
TemplateSyntaxError: Could not parse the remainder: '\'drug_search/js/reveal-master/plugin/notes/notes.js\'' from '\'drug_search/js/reveal-master/plugin/notes/notes.js\''
Not Found: /Reporpoise/plugin/highlight/highlight.js
Not Found: /Reporpoise/plugin/zoom-js/zoom.js
Not Found: /Reporpoise/plugin/highlight/highlight.js
Not Found: /Reporpoise/plugin/zoom-js/zoom.js
Not Found: /Reporpoise/plugin/highlight/highlight.js
Not Found: /Reporpoise/plugin/zoom-js/zoom.js
Not Found: /Reporpoise/127.0.0.1:8000/Reporpoise
Not Found: /Reporpoise/search
Not Found: /Reporpoise/search
Not Found: /
Not Found: /favicon.ico
