Not Found: /favicon.ico
Internal Server Error: /Reporpoise/associate
Traceback (most recent call last):
  File "/Library/Python/2.7/site-packages/django/core/handlers/base.py", line 132, in get_response
    response = wrapped_callback(request, *callback_args, **callback_kwargs)
  File "/Users/Dave/Desktop/Github/Reporpoise/drug_search/views.py", line 12, in gene_table
    return render(request, 'drug_search/gene_association.html')
  File "/Library/Python/2.7/site-packages/django/shortcuts/__init__.py", line 53, in render
    return HttpResponse(loader.render_to_string(*args, **kwargs),
  File "/Library/Python/2.7/site-packages/django/template/loader.py", line 116, in render_to_string
    template_name, context, context_instance, dirs, dictionary)
  File "/Library/Python/2.7/site-packages/django/template/engine.py", line 217, in render_to_string
    return t.render(context_instance)
  File "/Library/Python/2.7/site-packages/django/template/base.py", line 209, in render
    return self._render(context)
  File "/Library/Python/2.7/site-packages/django/template/base.py", line 201, in _render
    return self.nodelist.render(context)
  File "/Library/Python/2.7/site-packages/django/template/base.py", line 903, in render
    bit = self.render_node(node, context)
  File "/Library/Python/2.7/site-packages/django/template/debug.py", line 79, in render_node
    return node.render(context)
  File "/Library/Python/2.7/site-packages/django/template/loader_tags.py", line 135, in render
    return compiled_parent._render(context)
  File "/Library/Python/2.7/site-packages/django/template/base.py", line 201, in _render
    return self.nodelist.render(context)
  File "/Library/Python/2.7/site-packages/django/template/base.py", line 903, in render
    bit = self.render_node(node, context)
  File "/Library/Python/2.7/site-packages/django/template/debug.py", line 79, in render_node
    return node.render(context)
  File "/Library/Python/2.7/site-packages/django/template/loader_tags.py", line 65, in render
    result = block.nodelist.render(context)
  File "/Library/Python/2.7/site-packages/django/template/base.py", line 903, in render
    bit = self.render_node(node, context)
  File "/Library/Python/2.7/site-packages/django/template/debug.py", line 79, in render_node
    return node.render(context)
  File "/Library/Python/2.7/site-packages/django/template/defaulttags.py", line 507, in render
    six.reraise(*exc_info)
  File "/Library/Python/2.7/site-packages/django/template/defaulttags.py", line 493, in render
    url = reverse(view_name, args=args, kwargs=kwargs, current_app=current_app)
  File "/Library/Python/2.7/site-packages/django/core/urlresolvers.py", line 579, in reverse
    return force_text(iri_to_uri(resolver._reverse_with_prefix(view, prefix, *args, **kwargs)))
  File "/Library/Python/2.7/site-packages/django/core/urlresolvers.py", line 496, in _reverse_with_prefix
    (lookup_view_s, args, kwargs, len(patterns), patterns))
NoReverseMatch: Reverse for 'drug_search/js/gene_association.js' with arguments '()' and keyword arguments '{}' not found. 0 pattern(s) tried: []
Internal Server Error: /Reporpoise/associate
Traceback (most recent call last):
  File "/Library/Python/2.7/site-packages/django/core/handlers/base.py", line 132, in get_response
    response = wrapped_callback(request, *callback_args, **callback_kwargs)
  File "/Users/Dave/Desktop/Github/Reporpoise/drug_search/views.py", line 12, in gene_table
    return render(request, 'drug_search/gene_association.html')
  File "/Library/Python/2.7/site-packages/django/shortcuts/__init__.py", line 53, in render
    return HttpResponse(loader.render_to_string(*args, **kwargs),
  File "/Library/Python/2.7/site-packages/django/template/loader.py", line 116, in render_to_string
    template_name, context, context_instance, dirs, dictionary)
  File "/Library/Python/2.7/site-packages/django/template/engine.py", line 217, in render_to_string
    return t.render(context_instance)
  File "/Library/Python/2.7/site-packages/django/template/base.py", line 209, in render
    return self._render(context)
  File "/Library/Python/2.7/site-packages/django/template/base.py", line 201, in _render
    return self.nodelist.render(context)
  File "/Library/Python/2.7/site-packages/django/template/base.py", line 903, in render
    bit = self.render_node(node, context)
  File "/Library/Python/2.7/site-packages/django/template/debug.py", line 79, in render_node
    return node.render(context)
  File "/Library/Python/2.7/site-packages/django/template/loader_tags.py", line 135, in render
    return compiled_parent._render(context)
  File "/Library/Python/2.7/site-packages/django/template/base.py", line 201, in _render
    return self.nodelist.render(context)
  File "/Library/Python/2.7/site-packages/django/template/base.py", line 903, in render
    bit = self.render_node(node, context)
  File "/Library/Python/2.7/site-packages/django/template/debug.py", line 79, in render_node
    return node.render(context)
  File "/Library/Python/2.7/site-packages/django/template/loader_tags.py", line 65, in render
    result = block.nodelist.render(context)
  File "/Library/Python/2.7/site-packages/django/template/base.py", line 903, in render
    bit = self.render_node(node, context)
  File "/Library/Python/2.7/site-packages/django/template/debug.py", line 79, in render_node
    return node.render(context)
  File "/Library/Python/2.7/site-packages/django/template/defaulttags.py", line 507, in render
    six.reraise(*exc_info)
  File "/Library/Python/2.7/site-packages/django/template/defaulttags.py", line 493, in render
    url = reverse(view_name, args=args, kwargs=kwargs, current_app=current_app)
  File "/Library/Python/2.7/site-packages/django/core/urlresolvers.py", line 579, in reverse
    return force_text(iri_to_uri(resolver._reverse_with_prefix(view, prefix, *args, **kwargs)))
  File "/Library/Python/2.7/site-packages/django/core/urlresolvers.py", line 496, in _reverse_with_prefix
    (lookup_view_s, args, kwargs, len(patterns), patterns))
NoReverseMatch: Reverse for 'drug_search/js/gene_association.js' with arguments '()' and keyword arguments '{}' not found. 0 pattern(s) tried: []
Internal Server Error: /Reporpoise/networktize
Traceback (most recent call last):
  File "/Library/Python/2.7/site-packages/django/core/handlers/base.py", line 132, in get_response
    response = wrapped_callback(request, *callback_args, **callback_kwargs)
  File "/Users/Dave/Desktop/Github/Reporpoise/drug_search/views.py", line 126, in networktize
    gene_list = dict(ast.literal_eval(request.GET['genes'])).keys()
  File "/System/Library/Frameworks/Python.framework/Versions/2.7/lib/python2.7/ast.py", line 80, in literal_eval
    return _convert(node_or_string)
  File "/System/Library/Frameworks/Python.framework/Versions/2.7/lib/python2.7/ast.py", line 79, in _convert
    raise ValueError('malformed string')
ValueError: malformed string
Internal Server Error: /Reporpoise/networktize
Traceback (most recent call last):
  File "/Library/Python/2.7/site-packages/django/core/handlers/base.py", line 132, in get_response
    response = wrapped_callback(request, *callback_args, **callback_kwargs)
  File "/Users/Dave/Desktop/Github/Reporpoise/drug_search/views.py", line 126, in networktize
    gene_list = dict(ast.literal_eval(request.GET['genes'])).keys()
  File "/System/Library/Frameworks/Python.framework/Versions/2.7/lib/python2.7/ast.py", line 80, in literal_eval
    return _convert(node_or_string)
  File "/System/Library/Frameworks/Python.framework/Versions/2.7/lib/python2.7/ast.py", line 79, in _convert
    raise ValueError('malformed string')
ValueError: malformed string
Not Found: /drug_search
Not Found: /favicon.ico
Not Found: /favicon.ico
Not Found: /favicon.ico
Internal Server Error: /Reporpoise/search
Traceback (most recent call last):
  File "/Library/Python/2.7/site-packages/django/core/handlers/base.py", line 132, in get_response
    response = wrapped_callback(request, *callback_args, **callback_kwargs)
  File "/Users/Dave/Desktop/Github/Reporpoise/drug_search/views.py", line 48, in search
    gene_name = Gene.objects.filter(gene_id__iexact=gene_name)[0].gene_name
  File "/Library/Python/2.7/site-packages/django/db/models/query.py", line 201, in __getitem__
    return list(qs)[0]
IndexError: list index out of range
Not Found: /
Internal Server Error: /Reporpoise/network
Traceback (most recent call last):
  File "/Library/Python/2.7/site-packages/django/core/handlers/base.py", line 132, in get_response
    response = wrapped_callback(request, *callback_args, **callback_kwargs)
  File "/Users/Dave/Desktop/Github/Reporpoise/drug_search/views.py", line 31, in network
    return render(request,'drug_search/network.html',{"gene_network":json.dumps({gene_name:""}),"phenotypes":phenotypes,"mode":mode,"connection":connection,"source":source})
UnboundLocalError: local variable 'gene_name' referenced before assignment
Internal Server Error: /Reporpoise/network
Traceback (most recent call last):
  File "/Library/Python/2.7/site-packages/django/core/handlers/base.py", line 132, in get_response
    response = wrapped_callback(request, *callback_args, **callback_kwargs)
  File "/Users/Dave/Desktop/Github/Reporpoise/drug_search/views.py", line 31, in network
    return render(request,'drug_search/network.html',{"gene_network":json.dumps({gene_name:""}),"phenotypes":phenotypes,"mode":mode,"connection":connection,"source":source})
UnboundLocalError: local variable 'gene_name' referenced before assignment
Not Found: /Reporpoise/test.html
Not Found: /favicon.ico
Not Found: /favicon.ico
Internal Server Error: /Reporpoise/networktize
Traceback (most recent call last):
  File "/Library/Python/2.7/site-packages/django/core/handlers/base.py", line 132, in get_response
    response = wrapped_callback(request, *callback_args, **callback_kwargs)
  File "/Users/Dave/Desktop/Github/Reporpoise/drug_search/views.py", line 146, in networktize
    print interactoin.gene_target.gene_name
NameError: global name 'interactoin' is not defined
Internal Server Error: /Reporpoise/networktize
Traceback (most recent call last):
  File "/Library/Python/2.7/site-packages/django/core/handlers/base.py", line 132, in get_response
    response = wrapped_callback(request, *callback_args, **callback_kwargs)
  File "/Users/Dave/Desktop/Github/Reporpoise/drug_search/views.py", line 191, in networktize
    network_graph["links"].append({"source":interaction_indicies[interaction.gene_source.gene_name],"target":interaction_indicies[interaction.gene_target.gene_name],"type":case})
NameError: global name 'case' is not defined
Not Found: /favicon.ico
Not Found: /favicon.ico
Not Found: /Reporpoise/search
Not Found: /favicon.ico
Not Found: /favicon.ico
Not Found: /favicon.ico
Not Found: /favicon.ico
